<?xml version="1.0"?>
<robot name="mini_bot">

  <!-- Base Link -->
  <link name="base_link">
    <visual>
    <origin xyz="0.035 -0.028 0" rpy="0.0 0.0 3.14159"/>
      <geometry>
        <mesh filename="package://mini_bot_description/meshes/mini_bot_structure.stl" scale="0.001 0.001 0.001"/>
      </geometry>
      <material name="light_gray">
        <color rgba="0.8 0.8 0.8 1.0"/>
      </material>
    </visual>
    <collision>
      <origin xyz="-0.05 0.025 0.075" rpy="0 0 0"/>
      <geometry>
        <box size="0.2 0.15 0.15"/>
      </geometry>
    </collision>
    <inertial>
      <mass value="1.0"/>
      <inertia ixx="0.01" iyy="0.01" izz="0.01" ixy="0.0" ixz="0.0" iyz="0.0"/>
    </inertial>
  </link>

  <!-- Left Wheel -->
  <link name="left_wheel_link">
    <visual>
      <origin xyz="0 0 0" rpy="1.5708 0 0"/>
      <geometry>
        <mesh filename="package://mini_bot_description/meshes/mini_bot_wheel.stl" scale="0.001 0.001 0.001"/>
      </geometry>
      <material name="black">
        <color rgba="0 0 0 1.0"/>
      </material>
    </visual>
    <collision>
      <origin xyz="0 0 0" rpy="1.5708 0 0"/>
      <geometry>
        <cylinder radius="0.0325" length="0.02"/>
      </geometry>
    </collision>
    <inertial>
      <mass value="0.2"/>
      <inertia ixx="0.001" iyy="0.001" izz="0.001" ixy="0.0" ixz="0.0" iyz="0.0"/>
    </inertial>
  </link>

  <!-- Right Wheel -->
  <link name="right_wheel_link">
    <visual>
      <origin xyz="0 0 0" rpy="-1.57 0.0 0.0"/>
      <geometry>
        <mesh filename="package://mini_bot_description/meshes/mini_bot_wheel.stl" scale="0.001 0.001 0.001"/>
      </geometry>
      <material name="black">
        <color rgba="0 0 0 1.0"/>
      </material>
    </visual>
    <collision>
      <origin xyz="0 0 0" rpy="1.5708 0 0"/>
      <geometry>
        <cylinder radius="0.0325" length="0.02"/>
      </geometry>
    </collision>
    <inertial>
      <mass value="0.2"/>
      <inertia ixx="0.001" iyy="0.001" izz="0.001" ixy="0.0" ixz="0.0" iyz="0.0"/>
    </inertial>
  </link>

  <!-- Left Wheel Joint --> 
  <joint name="left_wheel_joint" type="continuous">
    <parent link="base_link"/>
    <child link="left_wheel_link"/>
    <origin xyz="0.0 0.08 0.0325" rpy="0 0 0"/>
    <axis xyz="0 1 0"/>
  </joint>

  <!-- Right Wheel Joint --> 
  <joint name="right_wheel_joint" type="continuous">
    <parent link="base_link"/>
    <child link="right_wheel_link"/>
    <origin xyz="0.0 -0.08 0.0325" rpy="0 0 0"/>
    <axis xyz="0 1 0"/>
  </joint>

  <!-- Sensor Links and Joints -->
  <link name="range_link"></link>
  <joint name="range_joint" type="fixed">
    <parent link="base_link"/>
    <child link="range_link"/>
    <origin xyz="0.08 0.0 0.06" rpy="0 1.57 0"/>
  </joint>

  <link name="camera_link"></link>
  <joint name="camera_joint" type="fixed">
    <parent link="base_link"/>
    <child link="camera_link"/>
    <origin xyz="0.105 -0.02 0.105" rpy="0 1.57 0"/>
  </joint>

  <link name="imu_link"></link>
  <joint name="imu_joint" type="fixed">
    <parent link="base_link"/>
    <child link="imu_link"/>
    <origin xyz="0.0 0.04 0.12" rpy="0 0 0"/>
  </joint>

</robot>
